<?xml version="1.0" ?>

<robot name="RB1">
    <gazebo reference="base_link">
        <material> Gazebo/Black</material>
    </gazebo>
    <gazebo reference="right_wheel">
        <material>Gazebo/RedGlow</material>
        <mu1 value="5.0"/>
		<mu2 value="0.5"/>
		<kp value="10000000.0" />
		<kd value="1.0" />
		<fdir1 value="1 0 0"/>
    </gazebo>
    <gazebo reference="left_wheel">
        <material>Gazebo/RedGlow</material>
        <mu1 value="5.0"/>
		<mu2 value="0.5"/>
		<kp value="10000000.0" />
		<kd value="1.0" />
		<fdir1 value="1 0 0"/>
    </gazebo>
    <gazebo reference="front_caster">
        <material>Gazebo/TurquoiseGlow</material>
        <mu1 value="0.0"/>
        <mu2 value="0.0"/>
        <kp value="10000000.0" />
        <kd value="100.0" />
        <fdir1 value="0 0 1"/>
    </gazebo>
    <gazebo reference="back_caster">
        <material>Gazebo/BlueGlow</material>
        <mu1 value="0.0"/>
        <mu2 value="0.0"/>
        <kp value="10000000.0" />
        <kd value="100.0" />
        <fdir1 value="0 0 1"/>
    </gazebo>
    <gazebo reference="front_laser">
        <material>Gazebo/Green</material>
    </gazebo>

    <gazebo>
        <plugin filename="libgazebo_ros_diff_drive.so" name="differential_drive_controller">
            <alwaysOn>true</alwaysOn>
            <updateRate>100</updateRate>
            <leftJoint>joint_base_left_wheel</leftJoint>
            <rightJoint>joint_base_right_wheel</rightJoint>
            <wheelSeparation>0.4</wheelSeparation>
            <wheelDiameter>0.05</wheelDiameter>
            <torque>10</torque>
            <commandTopic>cmd_vel</commandTopic>
            <odometryTopic>odom</odometryTopic>
            <odometryFrame>odom</odometryFrame>
            <robotBaseFrame>dummy_link</robotBaseFrame>
        </plugin>
    </gazebo>

    <gazebo reference="front_laser">
        <sensor type="ray" name="head_hokuyo_sensor">
            <pose>0 0 0 0 0 0</pose>
            <visualize>false</visualize>
            <update_rate>20</update_rate>
            <ray>
                <scan>
                    <horizontal>
                        <samples>720</samples>
                        <resolution>1</resolution>
                        <min_angle>-1.570796</min_angle>
                        <max_angle>1.570796</max_angle>
                    </horizontal>
                </scan>
                <range>
                    <min>0.04</min>
                    <max>10.0</max>
                    <resolution>0.01</resolution>
                </range>
                <noise>
                    <type>gaussian</type>
                    <mean>0.0</mean>
                    <stddev>0.01</stddev>
                </noise>
            </ray>
            <plugin name="gazebo_ros_head_hokuyo_controller" filename="libgazebo_ros_laser.so">
                <topicName>scan</topicName>
                <frameName>sensor_laser</frameName>
            </plugin>
        </sensor>
    </gazebo>
    <!-- Dummy root link -->
    <link name="dummy_link"/>

    <!-- Fixed joint connecting dummy_link to base_link -->
    <joint name="base_joint" type="fixed">
        <origin rpy="0 0 0" xyz="0 0 0.15" />
        <parent link="dummy_link"/>
        <child link="base_link"/>
    </joint>
    <!-- Link - base -->
    <link name="base_link">
        <inertial>
            <mass value="20" />
            <origin xyz="0 0 0" rpy="0 0 0" />
            <inertia ixx="0.4625" ixy="0" ixz="0" iyy="0.4625" iyz="0" izz="0.625" /> 
        </inertial>

        <collision>
            <origin rpy="0 0 0" xyz="0 0 0" />
            <geometry>
                <cylinder length="0.3" radius="0.25" />
            </geometry>
        </collision>

        <visual>
            <origin rpy="0 0 0" xyz="0 0 0" />
            <geometry>
                <cylinder length="0.3" radius="0.25" />
            </geometry>
            <material name="blue">
                <color rgba="0.15 0.33 1 1" />
            </material>
        </visual>
    </link>

    <!-- Joint - base / right wheel -->
    <joint name="joint_base_right_wheel" type="continuous">
        <origin rpy="0 0 0" xyz="0 -0.2 -0.15" />
        <child link="right_wheel" />
        <parent link="base_link" />
        <axis rpy="0 0 0" xyz="0 1 0" />
    </joint>
    <!-- Link - right wheel -->
    <link name="right_wheel">
        <inertial>
            <mass value="1" />
            <origin rpy="1.5707 0 0" xyz="0 0 0" /> 
            <inertia ixx="0.0002083" ixy="0" ixz="0" iyy="0.0003125" iyz="0" izz="0.0002083"/>
        </inertial>

        <collision>
            <origin rpy="1.5707 0 0" xyz="0 0 0" />
            <geometry>
                <cylinder length="0.025" radius="0.025"/>
            </geometry>
        </collision>
        <visual>
            <origin rpy="1.5707 0 0" xyz="0 0 0" />
            <geometry>
                <cylinder length="0.025" radius="0.025"/>
            </geometry>
        </visual>
    </link>

    <!-- Joint - base / left wheel -->
    <joint name="joint_base_left_wheel" type="continuous">
        <origin rpy="0 0 0" xyz="0 0.2 -0.15" />
        <child link="left_wheel" />
        <parent link="base_link" />
        <axis rpy="0 0 0" xyz="0 1 0" />
    </joint>
    <!-- Link - left wheel -->
    <link name="left_wheel">
        <inertial>
            <mass value="1" />
            <origin rpy="1.5707 0 0" xyz="0 0 0" />
            <inertia ixx="0.0002083" ixy="0" ixz="0" iyy="0.0003125" iyz="0" izz="0.0002083"/>
        </inertial>

        <collision>
            <origin rpy="1.5707 0 0" xyz="0 0 0" />
            <geometry>
                <cylinder length="0.025" radius="0.025"/>
            </geometry>
        </collision>
        <visual>
            <origin rpy="1.5707 0 0" xyz="0 0 0" />
            <geometry>
                <cylinder length="0.025" radius="0.025"/>
            </geometry>
        </visual>
    </link>

    <!-- Joint - base / front caster wheel -->
    <joint name="joint_base_front_caster" type="fixed">
        <origin rpy="0 0 0" xyz="0.1 0 -0.15" />
        <child link="front_caster" />
        <parent link="base_link" />
        <axis rpy="0 0 0" xyz="0 1 0" />
    </joint>
    <!-- Link - front caster wheel -->
    <link name="front_caster">
        <inertial>
            <mass value="1" />
            <origin xyz="0 0 0" rpy="0 0 0" />
            <inertia ixx="0.00025" ixy="0" ixz="0" iyy="0.00025" iyz="0" izz="0.00025"/>
        </inertial>

        <collision>
            <origin rpy="0 0 0" xyz="0 0 0" />
            <geometry>
                <sphere radius="0.025"/>
            </geometry>
        </collision>
        <visual>
            <origin rpy="0 0 0" xyz="0 0 0" />
            <geometry>
                <sphere radius="0.025"/>
            </geometry>
        </visual>
    </link>

    <!-- Joint - base / back caster wheel -->
    <joint name="joint_base_back_caster" type="fixed">
        <origin rpy="0 0 0" xyz="-0.1 0 -0.15" />
        <child link="back_caster" />
        <parent link="base_link" />
        <axis rpy="0 0 0" xyz="0 1 0" />
    </joint>
    <!-- Link - back caster wheel -->
    <link name="back_caster">
        <inertial>
            <mass value="1" />
            <origin xyz="0 0 0" rpy="0 0 0" />
            <inertia ixx="0.00025" ixy="0" ixz="0" iyy="0.00025" iyz="0" izz="0.00025"/>
        </inertial>

        <collision>
            <origin rpy="0 0 0" xyz="0 0 0" />
            <geometry>
                <sphere radius="0.025"/>
            </geometry>
        </collision>
        <visual>
            <origin rpy="0 0 0" xyz="0 0 0" />
            <geometry>
                <sphere radius="0.025"/>
            </geometry>
        </visual>
    </link>

    <!-- Joint - base / front laser -->
    <joint name="joint_base_front_laser" type="fixed">
        <origin rpy="3.141592 0 0" xyz="0.25 0 0.075" />
        <child link="front_laser" />
        <parent link="base_link" />
        <axis rpy="0 0 0" xyz="0 1 0" />
    </joint>
    <!-- Link - front laser -->
    <link name="front_laser">
        <inertial>
            <mass value="1" />
            <origin xyz="0 0 0" rpy="0 0 0" />
            <inertia ixx="0.0001521" ixy="0" ixz="0" iyy="0.0001521" iyz="0" izz="0.0002"/>
        </inertial>

        <collision>
            <origin rpy="0 0 0" xyz="0 0 0" />
            <geometry>
                <cylinder length="0.025" radius="0.02"/>
            </geometry>
        </collision>
        <visual>
            <origin rpy="0 0 0" xyz="0 0 0" />
            <geometry>
                <cylinder length="0.025" radius="0.02"/>
            </geometry>
        </visual>
    </link>

    <!-- Joint - base / base footprint -->
    <joint name="joint_base_base_footprint" type="fixed">
        <origin rpy="0 0 0" xyz="0 0 -0.15" />
        <child link="base_footprint" />
        <parent link="base_link" />
    </joint>
    <!-- Link - base footprint -->
    <link name="base_footprint">
    </link>
</robot>