<?xml version="1.0" ?>

<robot name="RB1">
    <gazebo reference="base_link">
        <material> Gazebo/Black</material>
    </gazebo>
    <gazebo reference="right_wheel">
        <material>Gazebo/RedGlow</material>
    </gazebo>
    <gazebo reference="left_wheel">
        <material>Gazebo/RedGlow</material>
    </gazebo>
    <gazebo reference="front_caster">
        <material>Gazebo/TurquoiseGlow</material>
    </gazebo>
    <gazebo reference="back_caster">
        <material>Gazebo/BlueGlow</material>
    </gazebo>
    <gazebo reference="front_laser">
        <material>Gazebo/Green</material>
    </gazebo>

    <!-- Link - base -->
    <link name="base_link">
        <inertial>
            <mass value="20" />
            <origin xyz="0 0 0" rpy="0 0 0" />
            <inertia ixx="0.4625" ixy="0" ixz="0" iyy="0.4625" iyz="0" izz="0.625" />
        </inertial>

        <collision>
            <origin rpy="0 0 0" xyz="0 0 0" />
            <geometry>
                <cylinder  length="0.3" radius="0.25" />
            </geometry>
        </collision>

        <visual>
            <origin rpy="0 0 0" xyz="0 0 0" />
            <geometry>
                <cylinder  length="0.3" radius="0.25" />
            </geometry>
            <material name="blue">
                <color rgba="0.15 0.33 1 1" />
            </material>
        </visual>
    </link>

    <!-- Joint - base / right wheel -->
    <joint name="joint_base_right_wheel" type="continuous">
        <origin rpy="0 0 0" xyz="0 -0.2 -0.15" />
        <child link="right_wheel" />
        <parent link="base_link" />
        <axis rpy="0 0 0" xyz="0 1 0" />
        <limit effort="10000" velocity="1000" />
        <joint_properties damping="1.0" friction="1.0" />
    </joint>
    <!-- Link - right wheel -->
    <link name="right_wheel">
        <inertial>
            <mass value="1" />
            <origin xyz="0 0 0" rpy="0 0 0" />
            <inertia ixx="0.0002083" ixy="0" ixz="0" iyy="0.0003125" iyz="0" izz="0.0002083"/>
        </inertial>

        <collision>
            <origin rpy="1.5707 0 0" xyz="0 0 0" />
            <geometry>
                <cylinder length="0.025" radius="0.025"/>
            </geometry>
        </collision>
        <visual>
            <origin rpy="1.5707 0 0" xyz="0 0 0" />
            <geometry>
                <cylinder length="0.025" radius="0.025"/>
            </geometry>
        </visual>
    </link>

    <!-- Joint - base / left wheel -->
    <joint name="joint_base_left_wheel" type="continuous">
        <origin rpy="0 0 0" xyz="0 0.2 -0.15" />
        <child link="left_wheel" />
        <parent link="base_link" />
        <axis rpy="0 0 0" xyz="0 1 0" />
        <limit effort="10000" velocity="1000" />
        <joint_properties damping="1.0" friction="1.0" />
    </joint>
    <!-- Link - left wheel -->
    <link name="left_wheel">
        <inertial>
            <mass value="1" />
            <origin xyz="0 0 0" rpy="0 0 0" />
            <inertia ixx="0.0002083" ixy="0" ixz="0" iyy="0.0003125" iyz="0" izz="0.0002083"/>
        </inertial>

        <collision>
            <origin rpy="1.5707 0 0" xyz="0 0 0" />
            <geometry>
                <cylinder length="0.025" radius="0.025"/>
            </geometry>
        </collision>
        <visual>
            <origin rpy="1.5707 0 0" xyz="0 0 0" />
            <geometry>
                <cylinder length="0.025" radius="0.025"/>
            </geometry>
        </visual>
    </link>

    <!-- Joint - base / front caster wheel -->
    <joint name="joint_base_front_caster" type="fixed">
        <origin rpy="0 0 0" xyz="0.1 0 -0.15" />
        <child link="front_caster" />
        <parent link="base_link" />
        <axis rpy="0 0 0" xyz="0 1 0" />
        <limit effort="10000" velocity="1000" />
        <joint_properties damping="1.0" friction="0.0" />
    </joint>
    <!-- Link - front caster wheel -->
    <link name="front_caster">
        <inertial>
            <mass value="1" />
            <origin xyz="0 0 0" rpy="0 0 0" />
            <inertia ixx="0.00025" ixy="0" ixz="0" iyy="0.00025" iyz="0" izz="0.00025"/>
        </inertial>

        <collision>
            <origin rpy="0 0 0" xyz="0 0 0" />
            <geometry>
                <sphere radius="0.025"/>
            </geometry>
        </collision>
        <visual>
            <origin rpy="0 0 0" xyz="0 0 0" />
            <geometry>
                <sphere radius="0.025"/>
            </geometry>
        </visual>
    </link>

    <!-- Joint - base / back caster wheel -->
    <joint name="joint_base_back_caster" type="fixed">
        <origin rpy="0 0 0" xyz="-0.1 0 -0.15" />
        <child link="back_caster" />
        <parent link="base_link" />
        <axis rpy="0 0 0" xyz="0 1 0" />
        <limit effort="10000" velocity="1000" />
        <joint_properties damping="1.0" friction="0.0" />
    </joint>
    <!-- Link - back caster wheel -->
    <link name="back_caster">
        <inertial>
            <mass value="1" />
            <origin xyz="0 0 0" rpy="0 0 0" />
            <inertia ixx="0.00025" ixy="0" ixz="0" iyy="0.00025" iyz="0" izz="0.00025"/>
        </inertial>

        <collision>
            <origin rpy="0 0 0" xyz="0 0 0" />
            <geometry>
                <sphere radius="0.025"/>
            </geometry>
        </collision>
        <visual>
            <origin rpy="0 0 0" xyz="0 0 0" />
            <geometry>
                <sphere radius="0.025"/>
            </geometry>
        </visual>
    </link>

    <!-- Joint - base / front laser -->
    <joint name="joint_base_front_laser" type="fixed">
        <origin rpy="3.141592 0 0" xyz="0.25 0 0.075" />
        <child link="front_laser" />
        <parent link="base_link" />
        <axis rpy="0 0 0" xyz="0 1 0" />
        <limit effort="10000" velocity="1000" />
        <joint_properties damping="1.0" friction="0.0" />
    </joint>
    <!-- Link - front laser -->
    <link name="front_laser">
        <inertial>
            <mass value="1" />
            <origin xyz="0 0 0" rpy="0 0 0" />
            <inertia ixx="0.0001521" ixy="0" ixz="0" iyy="0.0001521" iyz="0" izz="0.0002"/>
        </inertial>

        <collision>
            <origin rpy="0 0 0" xyz="0 0 0" />
            <geometry>
                <cylinder length="0.025" radius="0.02"/>
            </geometry>
        </collision>
        <visual>
            <origin rpy="0 0 0" xyz="0 0 0" />
            <geometry>
                <cylinder length="0.025" radius="0.02"/>
            </geometry>
        </visual>
    </link>

    <!-- Joint - base / base footprint -->
    <joint name="joint_base_base_footprint" type="fixed">
        <origin rpy="0 0 0" xyz="0 0 -0.15" />
        <child link="base_footprint" />
        <parent link="base_link" />
    </joint>
    <!-- Link - base footprint -->
    <link name="base_footprint">
    </link>
</robot>